<?xml version="1.0" encoding="utf-8"?>
<!-- This URDF was automatically created by SolidWorks to URDF Exporter! Originally created by Stephen Brawner (brawner@gmail.com) 
     Commit Version: 1.5.1-0-g916b5db  Build Version: 1.5.7152.31018
     For more information, please see http://wiki.ros.org/sw_urdf_exporter -->
<robot
  name="smr100l_description">
  <link
    name="base_link">
    <inertial>
      <origin
        xyz="0.00759473196950907 -0.000701025729209086 0.207930392353386"
        rpy="0 0 0" />
      <mass
        value="28.1550787286733" />
      <inertia
        ixx="0.694735350757739"
        ixy="-6.21396000769804E-05"
        ixz="-0.293894422173057"
        iyy="2.10954451452673"
        iyz="-0.00299922708479352"
        izz="2.29931755100392" />
    </inertial>
    <visual>
      <origin
        xyz="0 0 0"
        rpy="0 0 0" />
      <geometry>
        <mesh
          filename="package://smr100l_description/meshes/base_link.STL" />
      </geometry>
      <material
        name="">
        <color
          rgba="0.792156862745098 0.819607843137255 0.933333333333333 1" />
      </material>
    </visual>
    <collision>
      <origin
        xyz="0 0 0"
        rpy="0 0 0" />
      <geometry>
        <mesh
          filename="package://smr100l_description/meshes/base_link.STL" />
      </geometry>
    </collision>
  </link>
  <link
    name="swing_arm_left_link">
    <inertial>
      <origin
        xyz="-0.0776614816273194 -0.0395409626032495 -0.064306996898901"
        rpy="0 0 0" />
      <mass
        value="9.18443575420952" />
      <inertia
        ixx="0.0373380519861051"
        ixy="0.000826956322669333"
        ixz="-0.0122689989948566"
        iyy="0.0718057334451598"
        iyz="-0.00504042222250094"
        izz="0.0845455374881779" />
    </inertial>
    <visual>
      <origin
        xyz="0 0 0"
        rpy="0 0 0" />
      <geometry>
        <mesh
          filename="package://smr100l_description/meshes/swing_arm_left_link.STL" />
      </geometry>
      <material
        name="">
        <color
          rgba="0.752941176470588 0.752941176470588 0.752941176470588 1" />
      </material>
    </visual>
    <collision>
      <origin
        xyz="0 0 0"
        rpy="0 0 0" />
      <geometry>
        <mesh
          filename="package://smr100l_description/meshes/swing_arm_left_link.STL" />
      </geometry>
    </collision>
  </link>
  <joint
    name="swing_arm_left_joint"
    type="revolute">
    <origin
      xyz="0.1625 0.1975 0.15"
      rpy="0 0 0" />
    <parent
      link="base_link" />
    <child
      link="swing_arm_left_link" />
    <axis
      xyz="0 1 0" />
    <limit
      lower="-0.122"
      upper="0.122"
      effort="0"
      velocity="0" />
  </joint>
  <link
    name="caster_front_left_arm_link">
    <inertial>
      <origin
        xyz="-0.00817031848504823 0.000139775533481046 -0.0246700758933405"
        rpy="0 0 0" />
      <mass
        value="0.0620885720640709" />
      <inertia
        ixx="7.49165862568441E-05"
        ixy="2.64435018518839E-07"
        ixz="-2.23835197101876E-05"
        iyy="7.67735900801278E-05"
        iyz="5.50677002994071E-07"
        izz="5.14581828446636E-05" />
    </inertial>
    <visual>
      <origin
        xyz="0 0 0"
        rpy="0 0 0" />
      <geometry>
        <mesh
          filename="package://smr100l_description/meshes/caster_front_left_arm_link.STL" />
      </geometry>
      <material
        name="">
        <color
          rgba="0.792156862745098 0.819607843137255 0.933333333333333 1" />
      </material>
    </visual>
    <collision>
      <origin
        xyz="0 0 0"
        rpy="0 0 0" />
      <geometry>
        <mesh
          filename="package://smr100l_description/meshes/caster_front_left_arm_link.STL" />
      </geometry>
    </collision>
  </link>
  <joint
    name="caster_front_left_arm_joint"
    type="continuous">
    <origin
      xyz="0.162499999999997 0.0525000000000055 -0.00100000000000022"
      rpy="0 0 0" />
    <parent
      link="swing_arm_left_link" />
    <child
      link="caster_front_left_arm_link" />
    <axis
      xyz="0 0 1" />
  </joint>
  <link
    name="caster_front_left_wheel_link">
    <inertial>
      <origin
        xyz="7.54416921294743E-09 -2.04920247437457E-11 2.56866883574514E-06"
        rpy="0 0 0" />
      <mass
        value="0.352528491588121" />
      <inertia
        ixx="0.000426471882410058"
        ixy="-3.85473691740274E-08"
        ixz="6.22475468311631E-10"
        iyy="0.000776732615948867"
        iyz="-2.68998304669092E-10"
        izz="0.000426518098385309" />
    </inertial>
    <visual>
      <origin
        xyz="0 0 0"
        rpy="0 0 0" />
      <geometry>
        <mesh
          filename="package://smr100l_description/meshes/caster_front_left_wheel_link.STL" />
      </geometry>
      <material
        name="">
        <color
          rgba="0.792156862745098 0.819607843137255 0.933333333333333 1" />
      </material>
    </visual>
    <collision>
      <origin
        xyz="0 0 0"
        rpy="0 0 0" />
      <geometry>
        <mesh
          filename="package://smr100l_description/meshes/caster_front_left_wheel_link.STL" />
      </geometry>
    </collision>
  </link>
  <joint
    name="caster_front_left_wheel_joint"
    type="continuous">
    <origin
      xyz="-0.0379999999999835 0 -0.0865000000000086"
      rpy="0 1.5707963267949 0" />
    <parent
      link="caster_front_left_arm_link" />
    <child
      link="caster_front_left_wheel_link" />
    <axis
      xyz="0 1 0" />
  </joint>
  <link
    name="wheel_left_link">
    <inertial>
      <origin
        xyz="9.26789477547346E-05 3.32621059475624E-05 5.72059504728774E-08"
        rpy="0 0 0" />
      <mass
        value="4.95544635923129" />
      <inertia
        ixx="0.00871854767879788"
        ixy="-2.85508395278412E-06"
        ixz="2.70527344298056E-08"
        iyy="0.0157098593873516"
        iyz="-4.32877125311461E-09"
        izz="0.00872719589164137" />
    </inertial>
    <visual>
      <origin
        xyz="0 0 0"
        rpy="0 0 0" />
      <geometry>
        <mesh
          filename="package://smr100l_description/meshes/wheel_left_link.STL" />
      </geometry>
      <material
        name="">
        <color
          rgba="0.792156862745098 0.792156862745098 0.792156862745098 1" />
      </material>
    </visual>
    <collision>
      <origin
        xyz="0 0 0"
        rpy="0 0 0" />
      <geometry>
        <mesh
          filename="package://smr100l_description/meshes/wheel_left_link.STL" />
      </geometry>
    </collision>
  </link>
  <joint
    name="wheel_left_joint"
    type="continuous">
    <origin
      xyz="-0.1625 0.0495 -0.075"
      rpy="0 1.5708 0" />
    <parent
      link="swing_arm_left_link" />
    <child
      link="wheel_left_link" />
    <axis
      xyz="0 1 0" />
  </joint>
  <link
    name="swing_arm_right_link">
    <inertial>
      <origin
        xyz="-0.0776665293804929 0.0395418680626045 -0.0640244709559404"
        rpy="0 0 0" />
      <mass
        value="9.18423950420952" />
      <inertia
        ixx="0.0372801020470263"
        ixy="-0.000828920894039237"
        ixz="-0.0123404312816355"
        iyy="0.0717371511093358"
        iyz="0.0048289719106849"
        izz="0.0845342002890425" />
    </inertial>
    <visual>
      <origin
        xyz="0 0 0"
        rpy="0 0 0" />
      <geometry>
        <mesh
          filename="package://smr100l_description/meshes/swing_arm_right_link.STL" />
      </geometry>
      <material
        name="">
        <color
          rgba="0.752941176470588 0.752941176470588 0.752941176470588 1" />
      </material>
    </visual>
    <collision>
      <origin
        xyz="0 0 0"
        rpy="0 0 0" />
      <geometry>
        <mesh
          filename="package://smr100l_description/meshes/swing_arm_right_link.STL" />
      </geometry>
    </collision>
  </link>
  <joint
    name="swing_arm_right_joint"
    type="revolute">
    <origin
      xyz="0.1625 -0.1975 0.15"
      rpy="0 0 0" />
    <parent
      link="base_link" />
    <child
      link="swing_arm_right_link" />
    <axis
      xyz="0 1 0" />
    <limit
      lower="-0.122"
      upper="0.122"
      effort="0"
      velocity="0" />
  </joint>
  <link
    name="caster_front_right_arm_link">
    <inertial>
      <origin
        xyz="-0.00817031849669997 0.000139775509992363 -0.0246700759274692"
        rpy="0 0 0" />
      <mass
        value="0.0620885720820533" />
      <inertia
        ixx="7.4916586344645E-05"
        ixy="2.64434990167658E-07"
        ixz="-2.23835197563072E-05"
        iyy="7.67735901790732E-05"
        iyz="5.50676965248215E-07"
        izz="5.14581828745683E-05" />
    </inertial>
    <visual>
      <origin
        xyz="0 0 0"
        rpy="0 0 0" />
      <geometry>
        <mesh
          filename="package://smr100l_description/meshes/caster_front_right_arm_link.STL" />
      </geometry>
      <material
        name="">
        <color
          rgba="0.792156862745098 0.819607843137255 0.933333333333333 1" />
      </material>
    </visual>
    <collision>
      <origin
        xyz="0 0 0"
        rpy="0 0 0" />
      <geometry>
        <mesh
          filename="package://smr100l_description/meshes/caster_front_right_arm_link.STL" />
      </geometry>
    </collision>
  </link>
  <joint
    name="caster_front_right_arm_joint"
    type="continuous">
    <origin
      xyz="0.162500000000005 -0.0524999999999932 -0.001"
      rpy="0 0 0" />
    <parent
      link="swing_arm_right_link" />
    <child
      link="caster_front_right_arm_link" />
    <axis
      xyz="0 0 1" />
  </joint>
  <link
    name="caster_front_right_wheel_link">
    <inertial>
      <origin
        xyz="7.54774100858446E-09 5.16330866950909E-11 2.56865609338242E-06"
        rpy="0 0 0" />
      <mass
        value="0.352528489887363" />
      <inertia
        ixx="0.000426471881495556"
        ixy="-3.85473926465665E-08"
        ixz="6.22533069285731E-10"
        iyy="0.000776732615482017"
        iyz="-2.69300778723136E-10"
        izz="0.000426518097722264" />
    </inertial>
    <visual>
      <origin
        xyz="0 0 0"
        rpy="0 0 0" />
      <geometry>
        <mesh
          filename="package://smr100l_description/meshes/caster_front_right_wheel_link.STL" />
      </geometry>
      <material
        name="">
        <color
          rgba="0.792156862745098 0.819607843137255 0.933333333333333 1" />
      </material>
    </visual>
    <collision>
      <origin
        xyz="0 0 0"
        rpy="0 0 0" />
      <geometry>
        <mesh
          filename="package://smr100l_description/meshes/caster_front_right_wheel_link.STL" />
      </geometry>
    </collision>
  </link>
  <joint
    name="caster_front_right_wheel_joint"
    type="continuous">
    <origin
      xyz="-0.0379999999999961 0 -0.0865000000000046"
      rpy="0 1.5707963267949 0" />
    <parent
      link="caster_front_right_arm_link" />
    <child
      link="caster_front_right_wheel_link" />
    <axis
      xyz="0 1 0" />
  </joint>
  <link
    name="wheel_right_link">
    <inertial>
      <origin
        xyz="9.26789475841489E-05 -3.32621060119553E-05 -5.72059103568804E-08"
        rpy="0 0 0" />
      <mass
        value="4.95544635924954" />
      <inertia
        ixx="0.00871854767880613"
        ixy="2.85508393702444E-06"
        ixz="-2.70527246089045E-08"
        iyy="0.0157098593873957"
        iyz="-4.32876754653911E-09"
        izz="0.00872719589168907" />
    </inertial>
    <visual>
      <origin
        xyz="0 0 0"
        rpy="0 0 0" />
      <geometry>
        <mesh
          filename="package://smr100l_description/meshes/wheel_right_link.STL" />
      </geometry>
      <material
        name="">
        <color
          rgba="0.792156862745098 0.792156862745098 0.792156862745098 1" />
      </material>
    </visual>
    <collision>
      <origin
        xyz="0 0 0"
        rpy="0 0 0" />
      <geometry>
        <mesh
          filename="package://smr100l_description/meshes/wheel_right_link.STL" />
      </geometry>
    </collision>
  </link>
  <joint
    name="wheel_right_joint"
    type="continuous">
    <origin
      xyz="-0.1625 -0.0495 -0.075"
      rpy="0 1.5708 0" />
    <parent
      link="swing_arm_right_link" />
    <child
      link="wheel_right_link" />
    <axis
      xyz="0 1 0" />
  </joint>
  <link
    name="caster_rear_left_arm_link">
    <inertial>
      <origin
        xyz="-0.00817031850326078 0.00013977551742686 -0.0246700759265024"
        rpy="0 0 0" />
      <mass
        value="0.062088572117153" />
      <inertia
        ixx="7.49165863571816E-05"
        ixy="2.64434995969005E-07"
        ixz="-2.23835197549165E-05"
        iyy="7.67735901860121E-05"
        iyz="5.50676963526498E-07"
        izz="5.14581828901011E-05" />
    </inertial>
    <visual>
      <origin
        xyz="0 0 0"
        rpy="0 0 0" />
      <geometry>
        <mesh
          filename="package://smr100l_description/meshes/caster_rear_left_arm_link.STL" />
      </geometry>
      <material
        name="">
        <color
          rgba="0.792156862745098 0.819607843137255 0.933333333333333 1" />
      </material>
    </visual>
    <collision>
      <origin
        xyz="0 0 0"
        rpy="0 0 0" />
      <geometry>
        <mesh
          filename="package://smr100l_description/meshes/caster_rear_left_arm_link.STL" />
      </geometry>
    </collision>
  </link>
  <joint
    name="caster_rear_left_arm_joint"
    type="continuous">
    <origin
      xyz="-0.324999999999999 0.249999999999734 0.149"
      rpy="0 0 0" />
    <parent
      link="base_link" />
    <child
      link="caster_rear_left_arm_link" />
    <axis
      xyz="0 0 1" />
  </joint>
  <link
    name="caster_rear_left_wheel_link">
    <inertial>
      <origin
        xyz="7.54960193666276E-09 -0.499999999947538 2.56865689007846E-06"
        rpy="0 0 0" />
      <mass
        value="0.35252848990743" />
      <inertia
        ixx="0.000426471881504283"
        ixy="-3.85474028321326E-08"
        ixz="6.22523274154767E-10"
        iyy="0.000776732615509076"
        iyz="-2.6930513796899E-10"
        izz="0.000426518097749667" />
    </inertial>
    <visual>
      <origin
        xyz="0 0 0"
        rpy="0 0 0" />
      <geometry>
        <mesh
          filename="package://smr100l_description/meshes/caster_rear_left_wheel_link.STL" />
      </geometry>
      <material
        name="">
        <color
          rgba="0.792156862745098 0.819607843137255 0.933333333333333 1" />
      </material>
    </visual>
    <collision>
      <origin
        xyz="0 0 0"
        rpy="0 0 0" />
      <geometry>
        <mesh
          filename="package://smr100l_description/meshes/caster_rear_left_wheel_link.STL" />
      </geometry>
    </collision>
  </link>
  <joint
    name="caster_rear_left_wheel_joint"
    type="continuous">
    <origin
      xyz="-0.0379999999999835 0 -0.0864999999999982"
      rpy="0 1.5707963267949 0" />
    <parent
      link="caster_rear_left_arm_link" />
    <child
      link="caster_rear_left_wheel_link" />
    <axis
      xyz="0 1 0" />
  </joint>
  <link
    name="caster_rear_right_arm_link">
    <inertial>
      <origin
        xyz="-0.00817031850606931 0.000139775521451196 -0.0246700759261809"
        rpy="0 0 0" />
      <mass
        value="0.0620885721317263" />
      <inertia
        ixx="7.49165863625248E-05"
        ixy="2.64434999129066E-07"
        ixz="-2.23835197543855E-05"
        iyy="7.67735901889776E-05"
        iyz="5.50676962709383E-07"
        izz="5.14581828968603E-05" />
    </inertial>
    <visual>
      <origin
        xyz="0 0 0"
        rpy="0 0 0" />
      <geometry>
        <mesh
          filename="package://smr100l_description/meshes/caster_rear_right_arm_link.STL" />
      </geometry>
      <material
        name="">
        <color
          rgba="0.792156862745098 0.819607843137255 0.933333333333333 1" />
      </material>
    </visual>
    <collision>
      <origin
        xyz="0 0 0"
        rpy="0 0 0" />
      <geometry>
        <mesh
          filename="package://smr100l_description/meshes/caster_rear_right_arm_link.STL" />
      </geometry>
    </collision>
  </link>
  <joint
    name="caster_rear_right_arm_joint"
    type="continuous">
    <origin
      xyz="-0.324999999999996 -0.250000000000266 0.149"
      rpy="0 0 0" />
    <parent
      link="base_link" />
    <child
      link="caster_rear_right_arm_link" />
    <axis
      xyz="0 0 1" />
  </joint>
  <link
    name="caster_rear_right_wheel_link">
    <inertial>
      <origin
        xyz="7.54960197829613E-09 5.24615628716418E-11 2.56865688996744E-06"
        rpy="0 0 0" />
      <mass
        value="0.35252848990743" />
      <inertia
        ixx="0.000426471881504283"
        ixy="-3.85474028321326E-08"
        ixz="6.22523274154767E-10"
        iyy="0.000776732615509076"
        iyz="-2.69305137969016E-10"
        izz="0.000426518097749667" />
    </inertial>
    <visual>
      <origin
        xyz="0 0 0"
        rpy="0 0 0" />
      <geometry>
        <mesh
          filename="package://smr100l_description/meshes/caster_rear_right_wheel_link.STL" />
      </geometry>
      <material
        name="">
        <color
          rgba="0.792156862745098 0.819607843137255 0.933333333333333 1" />
      </material>
    </visual>
    <collision>
      <origin
        xyz="0 0 0"
        rpy="0 0 0" />
      <geometry>
        <mesh
          filename="package://smr100l_description/meshes/caster_rear_right_wheel_link.STL" />
      </geometry>
    </collision>
  </link>
  <joint
    name="caster_rear_right_wheel_joint"
    type="continuous">
    <origin
      xyz="-0.0379999999999961 0 -0.0864999999999942"
      rpy="0 1.5707963267949 0" />
    <parent
      link="caster_rear_right_arm_link" />
    <child
      link="caster_rear_right_wheel_link" />
    <axis
      xyz="0 1 0" />
  </joint>
  <link
    name="lidar_front_right_link">
    <inertial>
      <origin
        xyz="-0.000148096974669887 -3.2068342457614E-06 -0.0125826297979668"
        rpy="0 0 0" />
      <mass
        value="0.0481184286647859" />
      <inertia
        ixx="3.45484479551428E-05"
        ixy="-2.64598097532111E-09"
        ixz="-7.25415866375645E-08"
        iyy="3.46541328542382E-05"
        iyz="-1.62817624871116E-09"
        izz="5.23974453696245E-05" />
    </inertial>
    <visual>
      <origin
        xyz="0 0 0"
        rpy="0 0 0" />
      <geometry>
        <mesh
          filename="package://smr100l_description/meshes/lidar_front_right_link.STL" />
      </geometry>
      <material
        name="">
        <color
          rgba="0.498039215686275 0.498039215686275 0.498039215686275 1" />
      </material>
    </visual>
    <collision>
      <origin
        xyz="0 0 0"
        rpy="0 0 0" />
      <geometry>
        <mesh
          filename="package://smr100l_description/meshes/lidar_front_right_link.STL" />
      </geometry>
    </collision>
  </link>
  <joint
    name="lidar_front_right_joint"
    type="fixed">
    <origin
      xyz="0.440000000000006 -0.233500000000266 0.23335"
      rpy="0 0 0" />
    <parent
      link="base_link" />
    <child
      link="lidar_front_right_link" />
    <axis
      xyz="0 0 0" />
  </joint>
  <link
    name="lidar_rear_left_link">
    <inertial>
      <origin
        xyz="-0.000148095336834408 -3.20011052482028E-06 -0.0125826289547249"
        rpy="0 0 0" />
      <mass
        value="0.0481184302326393" />
      <inertia
        ixx="3.4548448557701E-05"
        ixy="-2.64868061332515E-09"
        ixz="-7.25417653009774E-08"
        iyy="3.46541307674242E-05"
        iyz="-1.62695057108891E-09"
        izz="5.23974446839416E-05" />
    </inertial>
    <visual>
      <origin
        xyz="0 0 0"
        rpy="0 0 0" />
      <geometry>
        <mesh
          filename="package://smr100l_description/meshes/lidar_rear_left_link.STL" />
      </geometry>
      <material
        name="">
        <color
          rgba="0.498039215686275 0.498039215686275 0.498039215686275 1" />
      </material>
    </visual>
    <collision>
      <origin
        xyz="0 0 0"
        rpy="0 0 0" />
      <geometry>
        <mesh
          filename="package://smr100l_description/meshes/lidar_rear_left_link.STL" />
      </geometry>
    </collision>
  </link>
  <joint
    name="lidar_rear_left_joint"
    type="fixed">
    <origin
      xyz="-0.44 0.2335 0.23335"
      rpy="0 0 -3.1416" />
    <parent
      link="base_link" />
    <child
      link="lidar_rear_left_link" />
    <axis
      xyz="0 0 0" />
  </joint>
  <link
    name="imu_link">
    <inertial>
      <origin
        xyz="-6.93505865298019E-05 2.10656642645446E-05 -0.001722725779644"
        rpy="0 0 0" />
      <mass
        value="0.000911356888660498" />
      <inertia
        ixx="2.85410348210611E-08"
        ixy="-2.22197427856955E-10"
        ixz="7.87903579180657E-11"
        iyy="4.9934643360849E-08"
        iyz="-4.13194761846969E-11"
        izz="7.78569805080499E-08" />
    </inertial>
    <visual>
      <origin
        xyz="0 0 0"
        rpy="0 0 0" />
      <geometry>
        <mesh
          filename="package://smr100l_description/meshes/imu_link.STL" />
      </geometry>
      <material
        name="">
        <color
          rgba="0.792156862745098 0.819607843137255 0.933333333333333 1" />
      </material>
    </visual>
    <collision>
      <origin
        xyz="0 0 0"
        rpy="0 0 0" />
      <geometry>
        <mesh
          filename="package://smr100l_description/meshes/imu_link.STL" />
      </geometry>
    </collision>
  </link>
  <joint
    name="imu_joint"
    type="fixed">
    <origin
      xyz="4.50000000024337E-05 0.000119999999742196 0.210000000000001"
      rpy="0 0 0" />
    <parent
      link="base_link" />
    <child
      link="imu_link" />
    <axis
      xyz="0 0 0" />
  </joint>
  <link
    name="depthcam_link">
    <inertial>
      <origin
        xyz="0.00150774564524087 0.0014060246130252 0.0124765926772498"
        rpy="0 0 0" />
      <mass
        value="0.0364722975832015" />
      <inertia
        ixx="2.34030280913361E-05"
        ixy="2.10290936540947E-07"
        ixz="1.01548325628649E-08"
        iyy="3.50609041662243E-06"
        iyz="1.72382791671337E-09"
        izz="2.36116348761219E-05" />
    </inertial>
    <visual>
      <origin
        xyz="0 0 0"
        rpy="0 0 0" />
      <geometry>
        <mesh
          filename="package://smr100l_description/meshes/depthcam_link.STL" />
      </geometry>
      <material
        name="">
        <color
          rgba="0.701960784313725 0.701960784313725 0.701960784313725 1" />
      </material>
    </visual>
    <collision>
      <origin
        xyz="0 0 0"
        rpy="0 0 0" />
      <geometry>
        <mesh
          filename="package://smr100l_description/meshes/depthcam_link.STL" />
      </geometry>
    </collision>
  </link>
  <joint
    name="depthcam_joint"
    type="fixed">
    <origin
      xyz="0.476732627888839 0 0.2675"
      rpy="0 0 0" />
    <parent
      link="base_link" />
    <child
      link="depthcam_link" />
    <axis
      xyz="0 0 0" />
  </joint>
  <link
    name="lifter_link">
    <inertial>
      <origin
        xyz="3.25632664729974E-05 0.00011879601216699 -0.0165650988158963"
        rpy="0 0 0" />
      <mass
        value="28.8633842413996" />
      <inertia
        ixx="0.464199941953465"
        ixy="0.000162736007880683"
        ixz="-1.3222231656386E-06"
        iyy="0.345046110863771"
        iyz="8.98295045138445E-07"
        izz="0.790316361239543" />
    </inertial>
    <visual>
      <origin
        xyz="0 0 0"
        rpy="0 0 0" />
      <geometry>
        <mesh
          filename="package://smr100l_description/meshes/lifter_link.STL" />
      </geometry>
      <material
        name="">
        <color
          rgba="0.752941176470588 0.752941176470588 0.752941176470588 1" />
      </material>
    </visual>
    <collision>
      <origin
        xyz="0 0 0"
        rpy="0 0 0" />
      <geometry>
        <mesh
          filename="package://smr100l_description/meshes/lifter_link.STL" />
      </geometry>
    </collision>
  </link>
  <joint
    name="lifter_joint"
    type="prismatic">
    <origin
      xyz="0 0 0.369"
      rpy="0 0 0" />
    <parent
      link="base_link" />
    <child
      link="lifter_link" />
    <axis
      xyz="0 0 1" />
    <limit
      lower="0"
      upper="0.05"
      effort="1000"
      velocity="0.00833" />
  </joint>
</robot>